Workbook

Sheet Tabellen Boxplots
D1: =SUBTOTAL(2,D4:D20) -> 13 | E1: =SUBTOTAL(2,E4:E20) -> 11 | F1: =SUBTOTAL(2,F4:F20) -> 14 | G1: =SUBTOTAL(2,G4:G20) -> 15 | H1: =SUBTOTAL(2,H4:H20) -> 17 | I1: =SUM(D1:H1) -> 70
D2: 18-20 | E2: 20-21 | F2: 21-22 | G2: 22-24 | H2: 24-30 | K2: 18-20 | L2: 20-21 | M2: 21-22 | N2: 22-24 | O2: 24-30
A4: 19 | B4: 160 | D4: =B4 -> 160 | E4: =B17 -> 160 | F4: =B28 -> 160 | G4: =B42 -> 155 | H4: =B57 -> 170 | J4: Min | K4: =QUARTILE($B$4:$B$16,0) -> 160 | L4: =QUARTILE($B$17:$B$27,0) -> 160 | M4: =QUARTILE($B$28:$B$41,0) -> 160 | N4: =QUARTILE($B$42:$B$56,0) -> 155 | O4: =QUARTILE($B$57:$B$73,0) -> 164
A5: 19 | B5: 168 | D5: =B5 -> 168 | E5: =B18 -> 163 | F5: =B29 -> 161 | G5: =B43 -> 160 | H5: =B58 -> 172 | J5: 0.25 | K5: =QUARTILE($B$4:$B$16,1) -> 168 | L5: =QUARTILE($B$4:$B$16,1) -> 168 | M5: =QUARTILE($B$28:$B$41,1) -> 166.25 | N5: =QUARTILE($B$42:$B$56,1) -> 170 | O5: =QUARTILE($B$57:$B$73,1) -> 175
A6: 19 | B6: 182 | D6: =B6 -> 182 | E6: =B19 -> 165 | F6: =B30 -> 165 | G6: =B44 -> 170 | H6: =B59 -> 176 | J6: 0.5 | K6: =QUARTILE($B$4:$B$16,2) -> 180 | L6: =QUARTILE($B$17:$B$27,2) -> 176 | M6: =QUARTILE($B$28:$B$41,2) -> 172 | N6: =QUARTILE($B$42:$B$56,2) -> 176 | O6: =QUARTILE($B$57:$B$73,2) -> 180
A7: 20 | B7: 163 | D7: =B7 -> 163 | E7: =B20 -> 173 | F7: =B31 -> 165 | G7: =B45 -> 176 | H7: =B60 -> 176 | J7: 0.75 | K7: =QUARTILE($B$4:$B$16,3) -> 183 | L7: =QUARTILE($B$17:$B$27,3) -> 181 | M7: =QUARTILE($B$28:$B$41,3) -> 183 | N7: =QUARTILE($B$42:$B$56,3) -> 182.5 | O7: =QUARTILE($B$57:$B$73,3) -> 185
A8: 20 | B8: 163 | D8: =B8 -> 163 | E8: =B21 -> 174 | F8: =B32 -> 170 | G8: =B46 -> 176 | H8: =B61 -> 178 | J8: Max | K8: =QUARTILE($B$4:$B$16,4) -> 195 | L8: =QUARTILE($B$17:$B$27,4) -> 185 | M8: =QUARTILE($B$28:$B$41,4) -> 188 | N8: =QUARTILE($B$42:$B$56,4) -> 193 | O8: =QUARTILE($B$57:$B$73,4) -> 193
A9: 20 | B9: 170 | D9: =B9 -> 170 | E9: =B22 -> 176 | F9: =B33 -> 170 | G9: =B47 -> 178 | H9: =B62 -> 180
A10: 20 | B10: 174 | D10: =B10 -> 174 | E10: =B23 -> 176 | F10: =B34 -> 170 | G10: =B48 -> 185 | H10: =B63 -> 183
A11: 20 | B11: 180 | D11: =B11 -> 180 | E11: =B24 -> 178 | F11: =B35 -> 174 | G11: =B49 -> 189 | H11: =B64 -> 187 | J11: unterer Fehlerindikator | K11: =K5-K4 -> 8 | L11: =L5-L4 -> 8 | M11: =M5-M4 -> 6.25 | N11: =N5-N4 -> 15 | O11: =O5-O4 -> 11
A12: 20 | B12: 182 | D12: =B12 -> 182 | E12: =B25 -> 184 | F12: =B36 -> 180 | G12: =B50 -> 193 | H12: =B65 -> 164 | J12: 0.25 | K12: =K5 -> 168 | L12: =L5 -> 168 | M12: =M5 -> 166.25 | N12: =N5 -> 170 | O12: =O5 -> 175
A13: 20 | B13: 183 | D13: =B13 -> 183 | E13: =B26 -> 185 | F13: =B37 -> 180 | G13: =B51 -> 160 | H13: =B66 -> 175 | J13: 0.5 | K13: =K6-K5 -> 12 | L13: =L6-L5 -> 8 | M13: =M6-M5 -> 5.75 | N13: =N6-N5 -> 6 | O13: =O6-O5 -> 5
A14: 20 | B14: 183 | D14: =B14 -> 183 | E14: =B27 -> 185 | F14: =B38 -> 184 | G14: =B52 -> 170 | H14: =B67 -> 182 | J14: 0.75 | K14: =K7-K6 -> 3 | L14: =L7-L6 -> 5 | M14: =M7-M6 -> 11 | N14: =N7-N6 -> 6.5 | O14: =O7-O6 -> 5
A15: 20 | B15: 185 | D15: =B15 -> 185 | F15: =B39 -> 185 | G15: =B53 -> 171 | H15: =B68 -> 184 | J15: oberer Fehlerindikator | K15: =K8-K7 -> 12 | L15: =L8-L7 -> 4 | M15: =M8-M7 -> 5 | N15: =N8-N7 -> 10.5 | O15: =O8-O7 -> 8
A16: 20 | B16: 195 | D16: =B16 -> 195 | F16: =B40 -> 187 | G16: =B54 -> 182 | H16: =B69 -> 185
A17: 21 | B17: 160 | F17: =B41 -> 188 | G17: =B55 -> 182 | H17: =B70 -> 185
A18: 21 | B18: 163 | G18: =B56 -> 183 | H18: =B71 -> 193
A19: 21 | B19: 165 | H19: =B72 -> 169
A20: 21 | B20: 173 | H20: =B73 -> 190
A21: 21 | B21: 174
A22: 21 | B22: 176 | D22: 18-20 | E22: 20-21 | F22: 21-22 | G22: 22-24 | H22: 24-30
A23: 21 | B23: 176 | C23: Min | D23: =QUARTILE($B$4:$B$16,0) -> 160 | E23: =QUARTILE($B$17:$B$27,0) -> 160 | F23: =QUARTILE($B$28:$B$41,0) -> 160 | G23: =QUARTILE($B$42:$B$56,0) -> 155 | H23: =QUARTILE($B$57:$B$73,0) -> 164
A24: 21 | B24: 178 | C24: 0.25 | D24: =QUARTILE($B$4:$B$16,1) -> 168 | E24: =QUARTILE($B$4:$B$16,1) -> 168 | F24: =QUARTILE($B$28:$B$41,1) -> 166.25 | G24: =QUARTILE($B$42:$B$56,1) -> 170 | H24: =QUARTILE($B$57:$B$73,1) -> 175
A25: 21 | B25: 184 | C25: 0.5 | D25: =QUARTILE($B$4:$B$16,2) -> 180 | E25: =QUARTILE($B$17:$B$27,2) -> 176 | F25: =QUARTILE($B$28:$B$41,2) -> 172 | G25: =QUARTILE($B$42:$B$56,2) -> 176 | H25: =QUARTILE($B$57:$B$73,2) -> 180
A26: 21 | B26: 185 | C26: 0.75 | D26: =QUARTILE($B$4:$B$16,3) -> 183 | E26: =QUARTILE($B$17:$B$27,3) -> 181 | F26: =QUARTILE($B$28:$B$41,3) -> 183 | G26: =QUARTILE($B$42:$B$56,3) -> 182.5 | H26: =QUARTILE($B$57:$B$73,3) -> 185
A27: 21 | B27: 185 | C27: Max | D27: =QUARTILE($B$4:$B$16,4) -> 195 | E27: =QUARTILE($B$17:$B$27,4) -> 185 | F27: =QUARTILE($B$28:$B$41,4) -> 188 | G27: =QUARTILE($B$42:$B$56,4) -> 193 | H27: =QUARTILE($B$57:$B$73,4) -> 193
A28: 22 | B28: 160
A29: 22 | B29: 161
A30: 22 | B30: 165
A31: 22 | B31: 165
A32: 22 | B32: 170
A33: 22 | B33: 170
A34: 22 | B34: 170
A35: 22 | B35: 174
A36: 22 | B36: 180
A37: 22 | B37: 180
A38: 22 | B38: 184
A39: 22 | B39: 185
... A73: 28 | B73: 190

Sheet Blasendiagramm
A3: Berufsausb. | B3: bi | C3: n | D3: n | E3: n | F3: n | G3: n | H3: j | I3: n | J3: n | K3: n | L3: n | M3: n | N3: j | O3: n | P3: n | Q3: n | R3: n | S3: n | T3: n | U3: n | V3: n | W3: n | X3: n | Y3: n | Z3: n | AA3: n | AB3: j | AC3: n | AD3: j | AE3: j | AF3: j | AG3: n | AH3: n | AI3: n | AJ3: j | AK3: n | AL3: n | AM3: n | AN3: n | AO3: j | AP3: n | AQ3: j | AR3: j | AS3: n | AT3: j | AU3: n | AV3: n | AW3: n | AX3: n | AY3: n | AZ3: n | BA3: n | BB3: j | BC3: n | BD3: j | BE3: n | BF3: n | BG3: n | BH3: j | BI3: n | BJ3: n | BK3: j | BL3: n | BM3: j | BN3: n | BO3: n | BP3: n | BQ3: j | BR3: n | BS3: n | BT3: n
A4: Geschlecht | B4: gi | C4: m | D4: m | E4: m | F4: m | G4: m | H4: m | I4: w | J4: w | K4: w | L4: w | M4: w | N4: m | O4: m | P4: w | Q4: w | R4: m | S4: m | T4: m | U4: w | V4: m | W4: m | X4: m | Y4: m | Z4: m | AA4: m | AB4: m | AC4: m | AD4: w | AE4: m | AF4: m | AG4: m | AH4: m | AI4: m | AJ4: w | AK4: w | AL4: w | AM4: w | AN4: w | AO4: m | AP4: m | AQ4: m | AR4: m | AS4: m | AT4: m | AU4: m | AV4: m | AW4: m | AX4: m | AY4: w | AZ4: m | BA4: w | BB4: m | BC4: m | BD4: w | BE4: w | BF4: m | BG4: m | BH4: m | BI4: m | BJ4: m | BK4: w | BL4: m | BM4: m | BN4: m | BO4: m | BP4: w | BQ4: w | BR4: m | BS4: w | BT4: w
C6: =IF(C3="n",TRUE,FALSE) -> TRUE | D6: =IF(D3="n",TRUE,FALSE) -> TRUE | E6: =IF(E3="n",TRUE,FALSE) -> TRUE | F6: =IF(F3="n",TRUE,FALSE) -> TRUE | G6: =IF(G3="n",TRUE,FALSE) -> TRUE | H6: =IF(H3="n",TRUE,FALSE) -> FALSE | I6: =IF(I3="n",TRUE,FALSE) -> TRUE | J6: =IF(J3="n",TRUE,FALSE) -> TRUE | ... BT6: =IF(BT3="n",TRUE,FALSE) -> TRUE
C7: =IF(C4="m",TRUE,FALSE) -> TRUE | D7: =IF(D4="m",TRUE,FALSE) -> TRUE | E7: =IF(E4="m",TRUE,FALSE) -> TRUE | F7: =IF(F4="m",TRUE,FALSE) -> TRUE | G7: =IF(G4="m",TRUE,FALSE) -> TRUE | H7: =IF(H4="m",TRUE,FALSE) -> TRUE | I7: =IF(I4="m",TRUE,FALSE) -> FALSE | J7: =IF(J4="m",TRUE,FALSE) -> FALSE | ... BT7: =IF(BT4="m",TRUE,FALSE) -> FALSE
B9: =SUM(C9:BT9) -> 35 | C9: =IF(AND(C6,C7),1,0) -> 1 | D9: =IF(AND(D6,D7),1,0) -> 1 | E9: =IF(AND(E6,E7),1,0) -> 1 | F9: =IF(AND(F6,F7),1,0) -> 1 | G9: =IF(AND(G6,G7),1,0) -> 1 | H9: =IF(AND(H6,H7),1,0) -> 0 | I9: =IF(AND(I6,I7),1,0) -> 0 | J9: =IF(AND(J6,J7),1,0) -> 0 | ... BT9: =IF(AND(BT6,BT7),1,0) -> 0
B10: =SUM(C10:BT10) -> 12 | C10: =IF(AND(NOT(C6),C7),1,0) -> 0 | D10: =IF(AND(NOT(D6),D7),1,0) -> 0 | E10: =IF(AND(NOT(E6),E7),1,0) -> 0 | F10: =IF(AND(NOT(F6),F7),1,0) -> 0 | G10: =IF(AND(NOT(G6),G7),1,0) -> 0 | H10: =IF(AND(NOT(H6),H7),1,0) -> 1 | I10: =IF(AND(NOT(I6),I7),1,0) -> 0 | J10: =IF(AND(NOT(J6),J7),1,0) -> 0 | ... BT10: =IF(AND(NOT(BT6),BT7),1,0) -> 0
B11: =SUM(C11:BT11) -> 18 | C11: =IF(AND(C6,NOT(C7)),1,0) -> 0 | D11: =IF(AND(D6,NOT(D7)),1,0) -> 0 | E11: =IF(AND(E6,NOT(E7)),1,0) -> 0 | F11: =IF(AND(F6,NOT(F7)),1,0) -> 0 | G11: =IF(AND(G6,NOT(G7)),1,0) -> 0 | H11: =IF(AND(H6,NOT(H7)),1,0) -> 0 | I11: =IF(AND(I6,NOT(I7)),1,0) -> 1 | J11: =IF(AND(J6,NOT(J7)),1,0) -> 1 | ... BT11: =IF(AND(BT6,NOT(BT7)),1,0) -> 1
B12: =SUM(C12:BT12) -> 5 | C12: =IF(AND(NOT(C6),NOT(C7)),1,0) -> 0 | D12: =IF(AND(NOT(D6),NOT(D7)),1,0) -> 0 | E12: =IF(AND(NOT(E6),NOT(E7)),1,0) -> 0 | F12: =IF(AND(NOT(F6),NOT(F7)),1,0) -> 0 | G12: =IF(AND(NOT(G6),NOT(G7)),1,0) -> 0 | H12: =IF(AND(NOT(H6),NOT(H7)),1,0) -> 0 | I12: =IF(AND(NOT(I6),NOT(I7)),1,0) -> 0 | J12: =IF(AND(NOT(J6),NOT(J7)),1,0) -> 0 | ... BT12: =IF(AND(NOT(BT6),NOT(BT7)),1,0) -> 0
B14: =SUM(B9:B12) -> 70
C20: b | D20: g | E20: n
C21: j | D21: m | E21: 12
C22: j | D22: w | E22: 5 | I22: =0.5 -> 0.5
C23: n | D23: m | E23: 35
C24: n | D24: w | E24: 18

Sheet Urlisten sortiert Größe
C2: Grundgesamtheit:
C3: zeitlich: | H3: WS 1718, 4.10.2017, Züge a & b
C4: räumlich: | H4: KL, Schoenstrasse, Hörsaal H4
C5: sachlich: | H5: Alle Hörer der LV "Statistik"
C7: Merkmalsausprägung: | H7: Alter [Jahre] | N7: Min | O7: =MIN(C15:CF15) -> 19 | Q7: Max | R7: =MAX(C15:CF15) -> 28
H8: Körperlänge [cm] | N8: Min | O8: =MIN(C16:CF16) -> 155 | Q8: Max | R8: =MAX(C16:CF16) -> 195 | Y8: =COUNTIF(BM18:BT18,"w") -> 0
H9: Berufausbildung [j/n]
H10: Geschlecht [m/w]
C12: Urliste | F12: =COUNT(C15:CF15) -> 70 | G12: Elemente
C13: Zug a | AR13: Zug b
A14: Element# | B14: wi | C14: 1 | D14: 2 | E14: 3 | F14: 4 | G14: 5 | H14: 6 | I14: 7 | J14: 8 | K14: 9 | L14: 10 | M14: 11 | N14: 12 | O14: 13 | P14: 14 | Q14: 15 | R14: 16 | S14: 17 | T14: 18 | U14: 19 | V14: 20 | W14: 21 | X14: 22 | Y14: 23 | Z14: 24 | AA14: 25 | AB14: 26 | AC14: 27 | AD14: 28 | AE14: 29 | AF14: 30 | AG14: 31 | AH14: 32 | AI14: 33 | AJ14: 34 | AK14: 35 | AL14: 36 | AM14: 37 | AN14: 38 | AO14: 39 | AP14: 40 | AQ14: 41 | AR14: 42 | AS14: 43 | AT14: 44 | AU14: 45 | AV14: 46 | AW14: 47 | AX14: 48 | AY14: 49 | AZ14: 50 | BA14: 51 | BB14: 52 | BC14: 53 | BD14: 54 | BE14: 55 | BF14: 56 | BG14: 57 | BH14: 58 | BI14: 59 | BJ14: 60 | BK14: 61 | BL14: 62 | BM14: 63 | BN14: 64 | BO14: 65 | BP14: 66 | BQ14: 67 | BR14: 68 | BS14: 69 | BT14: 70 | BU14: 71 | BV14: 72 | BW14: 73 | BX14: 74 | BY14: 75 | BZ14: 76 | CA14: 77 | CB14: 78 | CC14: 79 | CD14: 80 | CE14: 81 | CF14: 82 | CG14: 83 | CH14: 84 | CI14: 85 | CJ14: 86 | CK14: 87 | CL14: 88 | CM14: 89 | CN14: 90 | CO14: 91 | CP14: 92 | CQ14: 93 | CR14: 94 | CS14: 95 | CT14: 96 | CU14: 97 | CV14: 98 | CW14: 99 | CX14: 100 | CY14: 101 | CZ14: 102 | DA14: 103 | DB14: 104 | DC14: 105 | DD14: 106 | DE14: 107 | DF14: 108 | DG14: 109 | DH14: 110 | DI14: 111 | DJ14: 112 | DK14: 113 | DL14: 114 | DM14: 115 | DN14: 116 | DO14: 117 | DP14: 118 | DQ14: 119 | DR14: 120 | DS14: 121 | DT14: 122 | DU14: 123 | DV14: 124 | DW14: 125 | DX14: 126 | DY14: 127 | DZ14: 128 | EA14: 129 | EB14: 130 | EC14: 131 | ED14: 132 | EE14: 133 | EF14: 134 | EG14: 135 | EH14: 136 | EI14: 137 | EJ14: 138 | EK14: 139 | EL14: 140
A15: Alter | B15: xi | C15: 23 | D15: 19 | E15: 21 | F15: 22 | G15: 23 | H15: 24 | I15: 22 | J15: 20 | K15: 20 | L15: 21 | M15: 26 | N15: 21 | O15: 22 | P15: 22 | Q15: 19 | R15: 28 | S15: 20 | T15: 22 | U15: 22 | V15: 22 | W15: 23 | X15: 24 | Y15: 25 | Z15: 24 | AA15: 25 | AB15: 21 | AC15: 20 | AD15: 21 | AE15: 22 | AF15: 26 | AG15: 21 | AH15: 21 | AI15: 23 | AJ15: 23 | AK15: 25 | AL15: 25 | AM15: 21 | AN15: 23 | AO15: 25 | AP15: 20 | AQ15: 22 | AR15: 22 | AS15: 25 | AT15: 19 | AU15: 20 | AV15: 24 | AW15: 24 | AX15: 26 | AY15: 20 | AZ15: 20 | BA15: 24 | BB15: 25 | BC15: 21 | BD15: 22 | BE15: 26 | BF15: 20 | BG15: 21 | BH15: 21 | BI15: 22 | BJ15: 23 | BK15: 26 | BL15: 26 | BM15: 22 | BN15: 25 | BO15: 22 | BP15: 23 | BQ15: 28 | BR15: 23 | BS15: 27 | BT15: 20
A16: Köperlänge | B16: yi | C16: 155 | D16: 160 | E16: 160 | F16: 160 | G16: 160 | H16: 160 | I16: 161 | J16: 163 | K16: 163 | L16: 163 | M16: 164 | N16: 165 | O16: 165 | P16: 165 | Q16: 168 | R16: 169 | S16: 170 | T16: 170 | U16: 170 | V16: 170 | W16: 170 | X16: 170 | Y16: 170 | Z16: 171 | AA16: 172 | AB16: 173 | AC16: 174 | AD16: 174 | AE16: 174 | AF16: 175 | AG16: 176 | AH16: 176 | AI16: 176 | AJ16: 176 | AK16: 176 | AL16: 176 | AM16: 178 | AN16: 178 | AO16: 178 | AP16: 180 | AQ16: 180 | AR16: 180 | AS16: 180 | AT16: 182 | AU16: 182 | AV16: 182 | AW16: 182 | AX16: 182 | AY16: 183 | AZ16: 183 | BA16: 183 | BB16: 183 | BC16: 184 | BD16: 184 | BE16: 184 | BF16: 185 | BG16: 185 | BH16: 185 | BI16: 185 | BJ16: 185 | BK16: 185 | BL16: 185 | BM16: 187 | BN16: 187 | BO16: 188 | BP16: 189 | BQ16: 190 | BR16: 193 | BS16: 193 | BT16: 195
A17: Berufsausb. | B17: bi | C17: j | D17: n | E17: n | F17: n | G17: n | H17: n | I17: n | J17: n | K17: n | L17: n | M17: j | N17: n | O17: n | P17: n | Q17: n | R17: j | S17: n | T17: n | U17: n | V17: n | W17: n | X17: n | Y17: n | Z17: n | AA17: j | AB17: n | AC17: n | AD17: n | AE17: n | AF17: j | AG17: n | AH17: n | AI17: j | AJ17: j | AK17: j | AL17: j | AM17: n | AN17: n | AO17: n | AP17: n | AQ17: n | AR17: n | AS17: n | AT17: n | AU17: n | AV17: n | AW17: n | AX17: j | AY17: n | AZ17: n | BA17: n | BB17: j | BC17: n | BD17: n | BE17: j | BF17: n | BG17: n | BH17: n | BI17: n | BJ17: n | BK17: j | BL17: n | BM17: n | BN17: j | BO17: n | BP17: j | BQ17: j | BR17: n | BS17: j | BT17: n
A18: Geschlecht | B18: gi | C18: w | D18: w | E18: w | F18: w | G18: w | H18: w | I18: w | J18: w | K18: w | L18: w | M18: m | N18: m | O18: w | P18: w | Q18: w | R18: w | S18: w | T18: m | U18: w | V18: m | W18: m | X18: m | Y18: m | Z18: m | AA18: w | AB18: w | AC18: w | AD18: w | AE18: m | AF18: m | AG18: m | AH18: m | AI18: m | AJ18: m | AK18: w | AL18: w | AM18: m | AN18: m | AO18: m | AP18: m | AQ18: m | AR18: m | AS18: m | AT18: w | AU18: m | AV18: m | AW18: m | AX18: m | AY18: m | AZ18: m | BA18: m | BB18: m | BC18: m | BD18: m | BE18: m | BF18: m | BG18: m | BH18: m | BI18: m | BJ18: m | BK18: m | BL18: m | BM18: m | BN18: m | BO18: m | BP18: m | BQ18: m | BR18: m | BS18: m | BT18: m
C20: Zug b
C21: 42 | D21: 43 | E21: 44 | F21: 45 | G21: 46 | H21: 47 | I21: 48 | J21: 49 | K21: 50 | L21: 51 | M21: 52 | N21: 53 | O21: 54 | P21: 55 | Q21: 56 | R21: 57 | S21: 58 | T21: 59 | U21: 60 | V21: 61 | W21: 62 | X21: 63 | Y21: 64 | Z21: 65 | AA21: 66 | AB21: 67 | AC21: 68 | AD21: 69 | AE21: 70
C22: 22 | D22: 25 | E22: 19 | F22: 20 | G22: 24 | H22: 24 | I22: 26 | J22: 20 | K22: 20 | L22: 24 | M22: 25 | N22: 21 | O22: 22 | P22: 26 | Q22: 20 | R22: 21 | S22: 21 | T22: 22 | U22: 23 | V22: 26 | W22: 26 | X22: 22 | Y22: 25 | Z22: 22 | AA22: 23 | AB22: 28 | AC22: 23 | AD22: 27 | AE22: 20
C23: 180 | D23: 180 | E23: 182 | F23: 182 | G23: 182 | H23: 182 | I23: 182 | J23: 183 | K23: 183 | L23: 183 | M23: 183 | N23: 184 | O23: 184 | P23: 184 | Q23: 185 | R23: 185 | S23: 185 | T23: 185 | U23: 185 | V23: 185 | W23: 185 | X23: 187 | Y23: 187 | Z23: 188 | AA23: 189 | AB23: 190 | AC23: 193 | AD23: 193 | AE23: 195
C24: n | D24: n | E24: n | F24: n | G24: n | H24: n | I24: j | J24: n | K24: n | L24: n | M24: j | N24: n | O24: n | P24: j | Q24: n | R24: n | S24: n | T24: n | U24: n | V24: j | W24: n | X24: n | Y24: j | Z24: n | AA24: j | AB24: j | AC24: n | AD24: j | AE24: n
C25: m | D25: m | E25: w | F25: m | G25: m | H25: m | I25: m | J25: m | K25: m | L25: m | M25: m | N25: m | O25: m | P25: m | Q25: m | R25: m | S25: m | T25: m | U25: m | V25: m | W25: m | X25: m | Y25: m | Z25: m | AA25: m | AB25: m | AC25: m | AD25: m | AE25: m
C27: Urlisten, nach Zügen getrennt:
C29: Urliste Zug a | F29: =COUNT(C31:BT31) -> 41 | G29: Elemente
A30: Element# | B30: wi | C30: 1 | D30: 2 | E30: 3 | F30: 4 | G30: 5 | H30: 6 | I30: 7 | J30: 8 | K30: 9 | L30: 10 | M30: 11 | N30: 12 | O30: 13 | P30: 14 | Q30: 15 | R30: 16 | S30: 17 | T30: 18 | U30: 19 | V30: 20 | W30: 21 | X30: 22 | Y30: 23 | Z30: 24 | AA30: 25 | AB30: 26 | AC30: 27 | AD30: 28 | AE30: 29 | AF30: 30 | AG30: 31 | AH30: 32 | AI30: 33 | AJ30: 34 | AK30: 35 | AL30: 36 | AM30: 37 | AN30: 38 | AO30: 39 | AP30: 40 | AQ30: 41 | AR30: 42 | AS30: 43 | AT30: 44 | AU30: 45 | AV30: 46 | AW30: 47 | AX30: 48 | AY30: 49 | AZ30: 50 | BA30: 51 | BB30: 52 | BC30: 53 | BD30: 54 | BE30: 55 | BF30: 56 | BG30: 57 | BH30: 58 | BI30: 59 | BJ30: 60 | BK30: 61 | BL30: 62 | BM30: 63 | BN30: 64 | BO30: 65 | BP30: 66 | BQ30: 67 | BR30: 68 | BS30: 69 | BT30: 70
A31: Alter | B31: xi | C31: 19 | D31: 21 | E31: 24 | F31: 22 | G31: 20 | H31: 20 | I31: 21 | J31: 26 | K31: 21 | L31: 19 | M31: 28 | N31: 20 | O31: 22 | P31: 22 | Q31: 23 | R31: 24 | S31: 24 | T31: 25 | U31: 21 | V31: 20 | W31: 22 | X31: 21 | Y31: 21 | Z31: 20 | AA31: 22 | AB31: 22 | AC31: 20 | AD31: 24 | AE31: 26 | AF31: 24 | AG31: 25 | AH31: 21 | AI31: 21 | AJ31: 21 | AK31: 22 | AL31: 22 | AM31: 25 | AN31: 23 | AO31: 28 | AP31: 23 | AQ31: 27
A32: Köperlänge | B32: yi | C32: 160 | D32: 160 | E32: 160 | F32: 161 | G32: 163 | H32: 163 | I32: 163 | J32: 164 | K32: 165 | L32: 168 | M32: 169 | N32: 170 | O32: 170 | P32: 170 | Q32: 170 | R32: 170 | S32: 171 | T32: 172 | U32: 173 | V32: 174 | W32: 174 | X32: 176 | Y32: 178 | Z32: 180 | AA32: 180 | AB32: 180 | AC32: 182 | AD32: 182 | AE32: 182 | AF32: 183 | AG32: 183 | AH32: 184 | AI32: 185 | AJ32: 185 | AK32: 185 | AL32: 187 | AM32: 187 | AN32: 189 | AO32: 190 | AP32: 193 | AQ32: 193
A33: Berufsausb. | B33: bi | C33: n | D33: n | E33: n | F33: n | G33: n | H33: n | I33: n | J33: j | K33: n | L33: n | M33: j | N33: n | O33: n | P33: n | Q33: n | R33: n | S33: n | T33: j | U33: n | V33: n | W33: n | X33: n | Y33: n | Z33: n | AA33: n | AB33: n | AC33: n | AD33: n | AE33: j | AF33: n | AG33: j | AH33: n | AI33: n | AJ33: n | AK33: n | AL33: n | AM33: j | AN33: j | AO33: j | AP33: n | AQ33: j
A34: Geschlecht | B34: gi | C34: w | D34: w | E34: w | F34: w | G34: w | H34: w | I34: w | J34: m | K34: m | L34: w | M34: w | N34: w | O34: m | P34: w | Q34: m | R34: m | S34: m | T34: w | U34: w | V34: w | W34: m | X34: m | Y34: m | Z34: m | AA34: m | AB34: m | AC34: m | AD34: m | AE34: m | AF34: m | AG34: m | AH34: m | AI34: m | AJ34: m | AK34: m | AL34: m | AM34: m | AN34: m | AO34: m | AP34: m | AQ34: m
C37: Urliste Zug b | F37: =COUNT(C39:AE39) -> 29 | G37: Elemente
A38: Element# | B38: wi | C38: 1 | D38: 2 | E38: 3 | F38: 4 | G38: 5 | H38: 6 | I38: 7 | J38: 8 | K38: 9 | L38: 10 | M38: 11 | N38: 12 | O38: 13 | P38: 14 | Q38: 15 | R38: 16 | S38: 17 | T38: 18 | U38: 19 | V38: 20 | W38: 21 | X38: 22 | Y38: 23 | Z38: 24 | AA38: 25 | AB38: 26 | AC38: 27 | AD38: 28 | AE38: 29
A39: Alter | B39: xi | C39: 23 | D39: 22 | E39: 23 | F39: 22 | G39: 22 | H39: 22 | I39: 25 | J39: 21 | K39: 26 | L39: 21 | M39: 23 | N39: 23 | O39: 25 | P39: 25 | Q39: 23 | R39: 25 | S39: 25 | T39: 19 | U39: 24 | V39: 20 | W39: 20 | X39: 22 | Y39: 26 | Z39: 20 | AA39: 23 | AB39: 26 | AC39: 26 | AD39: 22 | AE39: 20
A40: Köperlänge | B40: yi | C40: 155 | D40: 160 | E40: 160 | F40: 165 | G40: 165 | H40: 170 | I40: 170 | J40: 174 | K40: 175 | L40: 176 | M40: 176 | N40: 176 | O40: 176 | P40: 176 | Q40: 178 | R40: 178 | S40: 180 | T40: 182 | U40: 182 | V40: 183 | W40: 183 | X40: 184 | Y40: 184 | Z40: 185 | AA40: 185 | AB40: 185 | AC40: 185 | AD40: 188 | AE40: 195
A41: Berufsausb. | B41: bi | C41: j | D41: n | E41: n | F41: n | G41: n | H41: n | I41: n | J41: n | K41: j | L41: n | M41: j | N41: j | O41: j | P41: j | Q41: n | R41: n | S41: n | T41: n | U41: n | V41: n | W41: n | X41: n | Y41: j | Z41: n | AA41: n | AB41: j | AC41: n | AD41: n | AE41: n
A42: Geschlecht | B42: gi | C42: w | D42: w | E42: w | F42: w | G42: w | H42: m | I42: m | J42: w | K42: m | L42: m | M42: m | N42: m | O42: w | P42: w | Q42: m | R42: m | S42: m | T42: w | U42: m | V42: m | W42: m | X42: m | Y42: m | Z42: m | AA42: m | AB42: m | AC42: m | AD42: m | AE42: m
G48: 23 | H48: 155 | I48: j | J48: w | O48: 19 | P48: 160 | Q48: n | R48: w | U48: 23 | V48: 155 | W48: j | X48: w
G49: 19 | H49: 160 | I49: n | J49: w | O49: 21 | P49: 160 | Q49: n | R49: w | U49: 22 | V49: 160 | W49: n | X49: w
G50: 21 | H50: 160 | I50: n | J50: w | O50: 24 | P50: 160 | Q50: n | R50: w | U50: 23 | V50: 160 | W50: n | X50: w
G51: 22 | H51: 160 | I51: n | J51: w | O51: 22 | P51: 161 | Q51: n | R51: w | U51: 22 | V51: 165 | W51: n | X51: w
G52: 23 | H52: 160 | I52: n | J52: w | O52: 20 | P52: 163 | Q52: n | R52: w | U52: 22 | V52: 165 | W52: n | X52: w
G53: 24 | H53: 160 | I53: n | J53: w | O53: 20 | P53: 163 | Q53: n | R53: w | U53: 22 | V53: 170 | W53: n | X53: m
...

Sheet Urlisten sortiert Alter
C2: Grundgesamtheit:
C3: zeitlich: | H3: WS 1718, 4.10.2017, Züge a & b
C4: räumlich: | H4: KL, Schoenstrasse, Hörsaal H4
C5: sachlich: | H5: Alle Hörer der LV "Statistik"
C7: Merkmalsausprägung: | H7: Alter [Jahre] | N7: Min | O7: =MIN(C15:CF15) -> 19 | Q7: Max | R7: =MAX(C15:CF15) -> 28
H8: Körperlänge [cm] | N8: Min | O8: =MIN(C16:CF16) -> 155 | Q8: Max | R8: =MAX(C16:CF16) -> 195
H9: Berufausbildung [j/n]
H10: Geschlecht [m/w]
C12: Urliste | F12: =COUNT(C15:CF15) -> 70 | G12: Elemente
C13: Zug a | AR13: Zug b
A14: Element# | B14: wi | C14: 1 | D14: 2 | E14: 3 | F14: 4 | G14: 5 | H14: 6 | I14: 7 | J14: 8 | K14: 9 | L14: 10 | M14: 11 | N14: 12 | O14: 13 | P14: 14 | Q14: 15 | R14: 16 | S14: 17 | T14: 18 | U14: 19 | V14: 20 | W14: 21 | X14: 22 | Y14: 23 | Z14: 24 | AA14: 25 | AB14: 26 | AC14: 27 | AD14: 28 | AE14: 29 | AF14: 30 | AG14: 31 | AH14: 32 | AI14: 33 | AJ14: 34 | AK14: 35 | AL14: 36 | AM14: 37 | AN14: 38 | AO14: 39 | AP14: 40 | AQ14: 41 | AR14: 42 | AS14: 43 | AT14: 44 | AU14: 45 | AV14: 46 | AW14: 47 | AX14: 48 | AY14: 49 | AZ14: 50 | BA14: 51 | BB14: 52 | BC14: 53 | BD14: 54 | BE14: 55 | BF14: 56 | BG14: 57 | BH14: 58 | BI14: 59 | BJ14: 60 | BK14: 61 | BL14: 62 | BM14: 63 | BN14: 64 | BO14: 65 | BP14: 66 | BQ14: 67 | BR14: 68 | BS14: 69 | BT14: 70 | BU14: 71 | BV14: 72 | BW14: 73 | BX14: 74 | BY14: 75 | BZ14: 76 | CA14: 77 | CB14: 78 | CC14: 79 | CD14: 80 | CE14: 81 | CF14: 82 | CG14: 83 | CH14: 84 | CI14: 85 | CJ14: 86 | CK14: 87 | CL14: 88 | CM14: 89 | CN14: 90 | CO14: 91 | CP14: 92 | CQ14: 93 | CR14: 94 | CS14: 95 | CT14: 96 | CU14: 97 | CV14: 98 | CW14: 99 | CX14: 100 | CY14: 101 | CZ14: 102 | DA14: 103 | DB14: 104 | DC14: 105 | DD14: 106 | DE14: 107 | DF14: 108 | DG14: 109 | DH14: 110 | DI14: 111 | DJ14: 112 | DK14: 113 | DL14: 114 | DM14: 115 | DN14: 116 | DO14: 117 | DP14: 118 | DQ14: 119 | DR14: 120 | DS14: 121 | DT14: 122 | DU14: 123 | DV14: 124 | DW14: 125 | DX14: 126 | DY14: 127 | DZ14: 128 | EA14: 129 | EB14: 130 | EC14: 131 | ED14: 132 | EE14: 133 | EF14: 134 | EG14: 135 | EH14: 136 | EI14: 137 | EJ14: 138 | EK14: 139 | EL14: 140
A15: Alter | B15: xi | C15: 19 | D15: 19 | E15: 19 | F15: 20 | G15: 20 | H15: 20 | I15: 20 | J15: 20 | K15: 20 | L15: 20 | M15: 20 | N15: 20 | O15: 20 | P15: 21 | Q15: 21 | R15: 21 | S15: 21 | T15: 21 | U15: 21 | V15: 21 | W15: 21 | X15: 21 | Y15: 21 | Z15: 21 | AA15: 22 | AB15: 22 | AC15: 22 | AD15: 22 | AE15: 22 | AF15: 22 | AG15: 22 | AH15: 22 | AI15: 22 | AJ15: 22 | AK15: 22 | AL15: 22 | AM15: 22 | AN15: 22 | AO15: 23 | AP15: 23 | AQ15: 23 | AR15: 23 | AS15: 23 | AT15: 23 | AU15: 23 | AV15: 23 | AW15: 23 | AX15: 24 | AY15: 24 | AZ15: 24 | BA15: 24 | BB15: 24 | BC15: 24 | BD15: 25 | BE15: 25 | BF15: 25 | BG15: 25 | BH15: 25 | BI15: 25 | BJ15: 25 | BK15: 25 | BL15: 26 | BM15: 26 | BN15: 26 | BO15: 26 | BP15: 26 | BQ15: 26 | BR15: 27 | BS15: 28 | BT15: 28
A16: Köperlänge | B16: yi | C16: 168 | D16: 160 | E16: 182 | F16: 163 | G16: 163 | H16: 182 | I16: 180 | J16: 170 | K16: 174 | L16: 185 | M16: 183 | N16: 195 | O16: 183 | P16: 178 | Q16: 163 | R16: 160 | S16: 184 | T16: 185 | U16: 185 | V16: 165 | W16: 176 | X16: 173 | Y16: 176 | Z16: 174 | AA16: 187 | AB16: 161 | AC16: 174 | AD16: 185 | AE16: 170 | AF16: 180 | AG16: 170 | AH16: 180 | AI16: 188 | AJ16: 160 | AK16: 165 | AL16: 170 | AM16: 184 | AN16: 165 | AO16: 170 | AP16: 193 | AQ16: 189 | AR16: 176 | AS16: 185 | AT16: 155 | AU16: 178 | AV16: 176 | AW16: 160 | AX16: 170 | AY16: 171 | AZ16: 160 | BA16: 182 | BB16: 183 | BC16: 182 | BD16: 187 | BE16: 183 | BF16: 172 | BG16: 176 | BH16: 180 | BI16: 178 | BJ16: 176 | BK16: 170 | BL16: 164 | BM16: 182 | BN16: 184 | BO16: 175 | BP16: 185 | BQ16: 185 | BR16: 193 | BS16: 169 | BT16: 190
A17: Berufsausb. | B17: bi | C17: n | D17: n | E17: n | F17: n | G17: n | H17: n | I17: n | J17: n | K17: n | L17: n | M17: n | N17: n | O17: n | P17: n | Q17: n | R17: n | S17: n | T17: n | U17: n | V17: n | W17: n | X17: n | Y17: n | Z17: n | AA17: n | AB17: n | AC17: n | AD17: n | AE17: n | AF17: n | AG17: n | AH17: n | AI17: n | AJ17: n | AK17: n | AL17: n | AM17: n | AN17: n | AO17: n | AP17: n | AQ17: j | AR17: j | AS17: n | AT17: j | AU17: n | AV17: j | AW17: n | AX17: n | AY17: n | AZ17: n | BA17: n | BB17: n | BC17: n | BD17: j | BE17: j | BF17: j | BG17: j | BH17: n | BI17: n | BJ17: j | BK17: n | BL17: j | BM17: j | BN17: j | BO17: j | BP17: j | BQ17: n | BR17: j | BS17: j | BT17: j
A18: Geschlecht | B18: gi | C18: w | D18: w | E18: w | F18: w | G18: w | H18: m | I18: m | J18: w | K18: w | L18: m | M18: m | N18: m | O18: m | P18: m | Q18: w | R18: w | S18: m | T18: m | U18: m | V18: m | W18: m | X18: w | Y18: m | Z18: w | AA18: m | AB18: w | AC18: m | AD18: m | AE18: m | AF18: m | AG18: w | AH18: m | AI18: m | AJ18: w | AK18: w | AL18: m | AM18: m | AN18: w | AO18: m | AP18: m | AQ18: m | AR18: m | AS18: m | AT18: w | AU18: m | AV18: m | AW18: w | AX18: m | AY18: m | AZ18: w | BA18: m | BB18: m | BC18: m | BD18: m | BE18: m | BF18: w | BG18: w | BH18: m | BI18: m | BJ18: w | BK18: m | BL18: m | BM18: m | BN18: m | BO18: m | BP18: m | BQ18: m | BR18: m | BS18: w | BT18: m
C20: Zug b
C21: 42 | D21: 43 | E21: 44 | F21: 45 | G21: 46 | H21: 47 | I21: 48 | J21: 49 | K21: 50 | L21: 51 | M21: 52 | N21: 53 | O21: 54 | P21: 55 | Q21: 56 | R21: 57 | S21: 58 | T21: 59 | U21: 60 | V21: 61 | W21: 62 | X21: 63 | Y21: 64 | Z21: 65 | AA21: 66 | AB21: 67 | AC21: 68 | AD21: 69 | AE21: 70
C22: 23 | D22: 23 | E22: 23 | F22: 23 | G22: 23 | H22: 23 | I22: 24 | J22: 24 | K22: 24 | L22: 24 | M22: 24 | N22: 24 | O22: 25 | P22: 25 | Q22: 25 | R22: 25 | S22: 25 | T22: 25 | U22: 25 | V22: 25 | W22: 26 | X22: 26 | Y22: 26 | Z22: 26 | AA22: 26 | AB22: 26 | AC22: 27 | AD22: 28 | AE22: 28
C23: 176 | D23: 185 | E23: 155 | F23: 178 | G23: 176 | H23: 160 | I23: 170 | J23: 171 | K23: 160 | L23: 182 | M23: 183 | N23: 182 | O23: 187 | P23: 183 | Q23: 172 | R23: 176 | S23: 180 | T23: 178 | U23: 176 | V23: 170 | W23: 164 | X23: 182 | Y23: 184 | Z23: 175 | AA23: 185 | AB23: 185 | AC23: 193 | AD23: 169 | AE23: 190
C24: j | D24: n | E24: j | F24: n | G24: j | H24: n | I24: n | J24: n | K24: n | L24: n | M24: n | N24: n | O24: j | P24: j | Q24: j | R24: j | S24: n | T24: n | U24: j | V24: n | W24: j | X24: j | Y24: j | Z24: j | AA24: j | AB24: n | AC24: j | AD24: j | AE24: j
C25: m | D25: m | E25: w | F25: m | G25: m | H25: w | I25: m | J25: m | K25: w | L25: m | M25: m | N25: m | O25: m | P25: m | Q25: w | R25: w | S25: m | T25: m | U25: w | V25: m | W25: m | X25: m | Y25: m | Z25: m | AA25: m | AB25: m | AC25: m | AD25: w | AE25: m
C27: Urlisten, nach Zügen getrennt:
C29: Urliste Zug a | F29: =COUNT(C31:BT31) -> 41 | G29: Elemente
A30: Element# | B30: wi | C30: 1 | D30: 2 | E30: 3 | F30: 4 | G30: 5 | H30: 6 | I30: 7 | J30: 8 | K30: 9 | L30: 10 | M30: 11 | N30: 12 | O30: 13 | P30: 14 | Q30: 15 | R30: 16 | S30: 17 | T30: 18 | U30: 19 | V30: 20 | W30: 21 | X30: 22 | Y30: 23 | Z30: 24 | AA30: 25 | AB30: 26 | AC30: 27 | AD30: 28 | AE30: 29 | AF30: 30 | AG30: 31 | AH30: 32 | AI30: 33 | AJ30: 34 | AK30: 35 | AL30: 36 | AM30: 37 | AN30: 38 | AO30: 39 | AP30: 40 | AQ30: 41 | AR30: 42 | AS30: 43 | AT30: 44 | AU30: 45 | AV30: 46 | AW30: 47 | AX30: 48 | AY30: 49 | AZ30: 50 | BA30: 51 | BB30: 52 | BC30: 53 | BD30: 54 | BE30: 55 | BF30: 56 | BG30: 57 | BH30: 58 | BI30: 59 | BJ30: 60 | BK30: 61 | BL30: 62 | BM30: 63 | BN30: 64 | BO30: 65 | BP30: 66 | BQ30: 67 | BR30: 68 | BS30: 69 | BT30: 70
A31: Alter | B31: xi | C31: 19 | D31: 19 | E31: 20 | F31: 20 | G31: 20 | H31: 20 | I31: 20 | J31: 20 | K31: 21 | L31: 21 | M31: 21 | N31: 21 | O31: 21 | P31: 21 | Q31: 21 | R31: 21 | S31: 21 | T31: 22 | U31: 22 | V31: 22 | W31: 22 | X31: 22 | Y31: 22 | Z31: 22 | AA31: 22 | AB31: 23 | AC31: 23 | AD31: 23 | AE31: 24 | AF31: 24 | AG31: 24 | AH31: 24 | AI31: 24 | AJ31: 25 | AK31: 25 | AL31: 25 | AM31: 26 | AN31: 26 | AO31: 27 | AP31: 28 | AQ31: 28
A32: Köperlänge | B32: yi | C32: 168 | D32: 160 | E32: 163 | F32: 163 | G32: 182 | H32: 180 | I32: 170 | J32: 174 | K32: 178 | L32: 163 | M32: 160 | N32: 184 | O32: 185 | P32: 185 | Q32: 165 | R32: 176 | S32: 173 | T32: 187 | U32: 161 | V32: 174 | W32: 185 | X32: 170 | Y32: 180 | Z32: 170 | AA32: 180 | AB32: 170 | AC32: 193 | AD32: 189 | AE32: 170 | AF32: 171 | AG32: 160 | AH32: 182 | AI32: 183 | AJ32: 187 | AK32: 183 | AL32: 172 | AM32: 164 | AN32: 182 | AO32: 193 | AP32: 169 | AQ32: 190
A33: Berufsausb. | B33: bi | C33: n | D33: n | E33: n | F33: n | G33: n | H33: n | I33: n | J33: n | K33: n | L33: n | M33: n | N33: n | O33: n | P33: n | Q33: n | R33: n | S33: n | T33: n | U33: n | V33: n | W33: n | X33: n | Y33: n | Z33: n | AA33: n | AB33: n | AC33: n | AD33: j | AE33: n | AF33: n | AG33: n | AH33: n | AI33: n | AJ33: j | AK33: j | AL33: j | AM33: j | AN33: j | AO33: j | AP33: j | AQ33: j
A34: Geschlecht | B34: gi | C34: w | D34: w | E34: w | F34: w | G34: m | H34: m | I34: w | J34: w | K34: m | L34: w | M34: w | N34: m | O34: m | P34: m | Q34: m | R34: m | S34: w | T34: m | U34: w | V34: m | W34: m | X34: m | Y34: m | Z34: w | AA34: m | AB34: m | AC34: m | AD34: m | AE34: m | AF34: m | AG34: w | AH34: m | AI34: m | AJ34: m | AK34: m | AL34: w | AM34: m | AN34: m | AO34: m | AP34: w | AQ34: m
C37: Urliste Zug b | F37: =COUNT(C39:AE39) -> 29 | G37: Elemente
A38: Element# | B38: wi | C38: 1 | D38: 2 | E38: 3 | F38: 4 | G38: 5 | H38: 6 | I38: 7 | J38: 8 | K38: 9 | L38: 10 | M38: 11 | N38: 12 | O38: 13 | P38: 14 | Q38: 15 | R38: 16 | S38: 17 | T38: 18 | U38: 19 | V38: 20 | W38: 21 | X38: 22 | Y38: 23 | Z38: 24 | AA38: 25 | AB38: 26 | AC38: 27 | AD38: 28 | AE38: 29
A39: Alter | B39: xi | C39: 19 | D39: 20 | E39: 20 | F39: 20 | G39: 20 | H39: 21 | I39: 21 | J39: 22 | K39: 22 | L39: 22 | M39: 22 | N39: 22 | O39: 22 | P39: 23 | Q39: 23 | R39: 23 | S39: 23 | T39: 23 | U39: 23 | V39: 24 | W39: 25 | X39: 25 | Y39: 25 | Z39: 25 | AA39: 25 | AB39: 26 | AC39: 26 | AD39: 26 | AE39: 26
A40: Köperlänge | B40: yi | C40: 182 | D40: 185 | E40: 183 | F40: 195 | G40: 183 | H40: 176 | I40: 174 | J40: 188 | K40: 160 | L40: 165 | M40: 170 | N40: 184 | O40: 165 | P40: 176 | Q40: 185 | R40: 155 | S40: 178 | T40: 176 | U40: 160 | V40: 182 | W40: 176 | X40: 180 | Y40: 178 | Z40: 176 | AA40: 170 | AB40: 184 | AC40: 175 | AD40: 185 | AE40: 185
A41: Berufsausb. | B41: bi | C41: n | D41: n | E41: n | F41: n | G41: n | H41: n | I41: n | J41: n | K41: n | L41: n | M41: n | N41: n | O41: n | P41: j | Q41: n | R41: j | S41: n | T41: j | U41: n | V41: n | W41: j | X41: n | Y41: n | Z41: j | AA41: n | AB41: j | AC41: j | AD41: j | AE41: n
A42: Geschlecht | B42: gi | C42: w | D42: m | E42: m | F42: m | G42: m | H42: m | I42: w | J42: m | K42: w | L42: w | M42: m | N42: m | O42: w | P42: m | Q42: m | R42: w | S42: m | T42: m | U42: w | V42: m | W42: w | X42: m | Y42: m | Z42: w | AA42: m | AB42: m | AC42: m | AD42: m | AE42: m
G48: 19 | H48: 168 | I48: n | J48: w | O48: 19 | P48: 168 | Q48: n | R48: w | U48: 19 | V48: 182 | W48: n | X48: w
G49: 19 | H49: 160 | I49: n | J49: w | O49: 19 | P49: 160 | Q49: n | R49: w | U49: 20 | V49: 185 | W49: n | X49: m
G50: 19 | H50: 182 | I50: n | J50: w | O50: 20 | P50: 163 | Q50: n | R50: w | U50: 20 | V50: 183 | W50: n | X50: m
G51: 20 | H51: 163 | I51: n | J51: w | O51: 20 | P51: 163 | Q51: n | R51: w | U51: 20 | V51: 195 | W51: n | X51: m
G52: 20 | H52: 163 | I52: n | J52: w | O52: 20 | P52: 182 | Q52: n | R52: m | U52: 20 | V52: 183 | W52: n | X52: m
G53: 20 | H53: 182 | I53: n | J53: m | O53: 20 | P53: 180 | Q53: n | R53: m | U53: 21 | V53: 176 | W53: n | X53: m
...

Sheet Urlisten
C2: Grundgesamtheit:
C3: zeitlich: | H3: WS 1718, 4.10.2017, Züge a & b
C4: räumlich: | H4: KL, Schoenstrasse, Hörsaal H4
C5: sachlich: | H5: Alle Hörer der LV "Statistik"
C7: Merkmalsausprägung: | H7: Alter [Jahre] | N7: Min | O7: =MIN(C15:CF15) -> 19 | Q7: Max | R7: =MAX(C15:CF15) -> 28
H8: Körperlänge [cm] | N8: Min | O8: =MIN(C16:CF16) -> 155 | Q8: Max | R8: =MAX(C16:CF16) -> 195
H9: Berufausbildung [j/n]
H10: Geschlecht [m/w]
C12: Urliste | F12: =COUNT(C15:CF15) -> 70 | G12: Elemente
C13: Zug a | AR13: Zug b
A14: Element# | B14: wi | C14: 1 | D14: 2 | E14: 3 | F14: 4 | G14: 5 | H14: 6 | I14: 7 | J14: 8 | K14: 9 | L14: 10 | M14: 11 | N14: 12 | O14: 13 | P14: 14 | Q14: 15 | R14: 16 | S14: 17 | T14: 18 | U14: 19 | V14: 20 | W14: 21 | X14: 22 | Y14: 23 | Z14: 24 | AA14: 25 | AB14: 26 | AC14: 27 | AD14: 28 | AE14: 29 | AF14: 30 | AG14: 31 | AH14: 32 | AI14: 33 | AJ14: 34 | AK14: 35 | AL14: 36 | AM14: 37 | AN14: 38 | AO14: 39 | AP14: 40 | AQ14: 41 | AR14: 42 | AS14: 43 | AT14: 44 | AU14: 45 | AV14: 46 | AW14: 47 | AX14: 48 | AY14: 49 | AZ14: 50 | BA14: 51 | BB14: 52 | BC14: 53 | BD14: 54 | BE14: 55 | BF14: 56 | BG14: 57 | BH14: 58 | BI14: 59 | BJ14: 60 | BK14: 61 | BL14: 62 | BM14: 63 | BN14: 64 | BO14: 65 | BP14: 66 | BQ14: 67 | BR14: 68 | BS14: 69 | BT14: 70 | BU14: 71 | BV14: 72 | BW14: 73 | BX14: 74 | BY14: 75 | BZ14: 76 | CA14: 77 | CB14: 78 | CC14: 79 | CD14: 80 | CE14: 81 | CF14: 82 | CG14: 83 | CH14: 84 | CI14: 85 | CJ14: 86 | CK14: 87 | CL14: 88 | CM14: 89 | CN14: 90 | CO14: 91 | CP14: 92 | CQ14: 93 | CR14: 94 | CS14: 95 | CT14: 96 | CU14: 97 | CV14: 98 | CW14: 99 | CX14: 100 | CY14: 101 | CZ14: 102 | DA14: 103 | DB14: 104 | DC14: 105 | DD14: 106 | DE14: 107 | DF14: 108 | DG14: 109 | DH14: 110 | DI14: 111 | DJ14: 112 | DK14: 113 | DL14: 114 | DM14: 115 | DN14: 116 | DO14: 117 | DP14: 118 | DQ14: 119 | DR14: 120 | DS14: 121 | DT14: 122 | DU14: 123 | DV14: 124 | DW14: 125 | DX14: 126 | DY14: 127 | DZ14: 128 | EA14: 129 | EB14: 130 | EC14: 131 | ED14: 132 | EE14: 133 | EF14: 134 | EG14: 135 | EH14: 136 | EI14: 137 | EJ14: 138 | EK14: 139 | EL14: 140
A15: Alter | B15: xi | C15: 22 | D15: 21 | E15: 23 | F15: 24 | G15: 24 | H15: 27 | I15: 19 | J15: 19 | K15: 21 | L15: 22 | M15: 21 | N15: 26 | O15: 22 | P15: 24 | Q15: 20 | R15: 23 | S15: 21 | T15: 22 | U15: 20 | V15: 24 | W15: 21 | X15: 22 | Y15: 22 | Z15: 20 | AA15: 21 | AB15: 26 | AC15: 24 | AD15: 28 | AE15: 25 | AF15: 25 | AG15: 21 | AH15: 21 | AI15: 20 | AJ15: 25 | AK15: 22 | AL15: 20 | AM15: 21 | AN15: 20 | AO15: 23 | AP15: 22 | AQ15: 28 | AR15: 26 | AS15: 21 | AT15: 23 | AU15: 22 | AV15: 20 | AW15: 24 | AX15: 20 | AY15: 19 | AZ15: 23 | BA15: 22 | BB15: 26 | BC15: 20 | BD15: 25 | BE15: 22 | BF15: 25 | BG15: 22 | BH15: 26 | BI15: 25 | BJ15: 22 | BK15: 23 | BL15: 23 | BM15: 23 | BN15: 20 | BO15: 26 | BP15: 21 | BQ15: 25 | BR15: 25 | BS15: 22 | BT15: 23
A16: Köperlänge | B16: yi | C16: 187 | D16: 178 | E16: 170 | F16: 170 | G16: 171 | H16: 193 | I16: 168 | J16: 160 | K16: 163 | L16: 161 | M16: 160 | N16: 164 | O16: 174 | P16: 160 | Q16: 163 | R16: 193 | S16: 184 | T16: 185 | U16: 163 | V16: 182 | W16: 185 | X16: 170 | Y16: 180 | Z16: 182 | AA16: 185 | AB16: 182 | AC16: 183 | AD16: 169 | AE16: 187 | AF16: 183 | AG16: 165 | AH16: 176 | AI16: 180 | AJ16: 172 | AK16: 170 | AL16: 170 | AM16: 173 | AN16: 174 | AO16: 189 | AP16: 180 | AQ16: 190 | AR16: 184 | AS16: 176 | AT16: 176 | AU16: 188 | AV16: 185 | AW16: 182 | AX16: 183 | AY16: 182 | AZ16: 185 | BA16: 160 | BB16: 175 | BC16: 195 | BD16: 176 | BE16: 165 | BF16: 180 | BG16: 170 | BH16: 185 | BI16: 178 | BJ16: 184 | BK16: 155 | BL16: 178 | BM16: 176 | BN16: 183 | BO16: 185 | BP16: 174 | BQ16: 176 | BR16: 170 | BS16: 165 | BT16: 160
A17: Berufsausb. | B17: bi | C17: n | D17: n | E17: n | F17: n | G17: n | H17: j | I17: n | J17: n | K17: n | L17: n | M17: n | N17: j | O17: n | P17: n | Q17: n | R17: n | S17: n | T17: n | U17: n | V17: n | W17: n | X17: n | Y17: n | Z17: n | AA17: n | AB17: j | AC17: n | AD17: j | AE17: j | AF17: j | AG17: n | AH17: n | AI17: n | AJ17: j | AK17: n | AL17: n | AM17: n | AN17: n | AO17: j | AP17: n | AQ17: j | AR17: j | AS17: n | AT17: j | AU17: n | AV17: n | AW17: n | AX17: n | AY17: n | AZ17: n | BA17: n | BB17: j | BC17: n | BD17: j | BE17: n | BF17: n | BG17: n | BH17: j | BI17: n | BJ17: n | BK17: j | BL17: n | BM17: j | BN17: n | BO17: n | BP17: n | BQ17: j | BR17: n | BS17: n | BT17: n
A18: Geschlecht | B18: gi | C18: m | D18: m | E18: m | F18: m | G18: m | H18: m | I18: w | J18: w | K18: w | L18: w | M18: w | N18: m | O18: m | P18: w | Q18: w | R18: m | S18: m | T18: m | U18: w | V18: m | W18: m | X18: m | Y18: m | Z18: m | AA18: m | AB18: m | AC18: m | AD18: w | AE18: m | AF18: m | AG18: m | AH18: m | AI18: m | AJ18: w | AK18: w | AL18: w | AM18: w | AN18: w | AO18: m | AP18: m | AQ18: m | AR18: m | AS18: m | AT18: m | AU18: m | AV18: m | AW18: m | AX18: m | AY18: w | AZ18: m | BA18: w | BB18: m | BC18: m | BD18: w | BE18: w | BF18: m | BG18: m | BH18: m | BI18: m | BJ18: m | BK18: w | BL18: m | BM18: m | BN18: m | BO18: m | BP18: w | BQ18: w | BR18: m | BS18: w | BT18: w
C21: Urlisten, nach Zügen getrennt:
C23: Urliste Zug a | F23: =COUNT(C25:BT25) -> 41 | G23: Elemente
A24: Element# | B24: wi | C24: 1 | D24: 2 | E24: 3 | F24: 4 | G24: 5 | H24: 6 | I24: 7 | J24: 8 | K24: 9 | L24: 10 | M24: 11 | N24: 12 | O24: 13 | P24: 14 | Q24: 15 | R24: 16 | S24: 17 | T24: 18 | U24: 19 | V24: 20 | W24: 21 | X24: 22 | Y24: 23 | Z24: 24 | AA24: 25 | AB24: 26 | AC24: 27 | AD24: 28 | AE24: 29 | AF24: 30 | AG24: 31 | AH24: 32 | AI24: 33 | AJ24: 34 | AK24: 35 | AL24: 36 | AM24: 37 | AN24: 38 | AO24: 39 | AP24: 40 | AQ24: 41 | AR24: 42 | AS24: 43 | AT24: 44 | AU24: 45 | AV24: 46 | AW24: 47 | AX24: 48 | AY24: 49 | AZ24: 50 | BA24: 51 | BB24: 52 | BC24: 53 | BD24: 54 | BE24: 55 | BF24: 56 | BG24: 57 | BH24: 58 | BI24: 59 | BJ24: 60 | BK24: 61 | BL24: 62 | BM24: 63 | BN24: 64 | BO24: 65 | BP24: 66 | BQ24: 67 | BR24: 68 | BS24: 69 | BT24: 70
A25: Alter | B25: xi | C25: 22 | D25: 21 | E25: 23 | F25: 24 | G25: 24 | H25: 27 | I25: 19 | J25: 19 | K25: 21 | L25: 22 | M25: 21 | N25: 26 | O25: 22 | P25: 24 | Q25: 20 | R25: 23 | S25: 21 | T25: 22 | U25: 20 | V25: 24 | W25: 21 | X25: 22 | Y25: 22 | Z25: 20 | AA25: 21 | AB25: 26 | AC25: 24 | AD25: 28 | AE25: 25 | AF25: 25 | AG25: 21 | AH25: 21 | AI25: 20 | AJ25: 25 | AK25: 22 | AL25: 20 | AM25: 21 | AN25: 20 | AO25: 23 | AP25: 22 | AQ25: 28
A26: Köperlänge | B26: yi | C26: 187 | D26: 178 | E26: 170 | F26: 170 | G26: 171 | H26: 193 | I26: 168 | J26: 160 | K26: 163 | L26: 161 | M26: 160 | N26: 164 | O26: 174 | P26: 160 | Q26: 163 | R26: 193 | S26: 184 | T26: 185 | U26: 163 | V26: 182 | W26: 185 | X26: 170 | Y26: 180 | Z26: 182 | AA26: 185 | AB26: 182 | AC26: 183 | AD26: 169 | AE26: 187 | AF26: 183 | AG26: 165 | AH26: 176 | AI26: 180 | AJ26: 172 | AK26: 170 | AL26: 170 | AM26: 173 | AN26: 174 | AO26: 189 | AP26: 180 | AQ26: 190
A27: Berufsausb. | B27: bi | C27: n | D27: n | E27: n | F27: n | G27: n | H27: j | I27: n | J27: n | K27: n | L27: n | M27: n | N27: j | O27: n | P27: n | Q27: n | R27: n | S27: n | T27: n | U27: n | V27: n | W27: n | X27: n | Y27: n | Z27: n | AA27: n | AB27: j | AC27: n | AD27: j | AE27: j | AF27: j | AG27: n | AH27: n | AI27: n | AJ27: j | AK27: n | AL27: n | AM27: n | AN27: n | AO27: j | AP27: n | AQ27: j
A28: Geschlecht | B28: gi | C28: m | D28: m | E28: m | F28: m | G28: m | H28: m | I28: w | J28: w | K28: w | L28: w | M28: w | N28: m | O28: m | P28: w | Q28: w | R28: m | S28: m | T28: m | U28: w | V28: m | W28: m | X28: m | Y28: m | Z28: m | AA28: m | AB28: m | AC28: m | AD28: w | AE28: m | AF28: m | AG28: m | AH28: m | AI28: m | AJ28: w | AK28: w | AL28: w | AM28: w | AN28: w | AO28: m | AP28: m | AQ28: m
C31: Urliste Zug b | F31: =COUNT(C33:BT33) -> 29 | G31: Elemente
A32: Element# | B32: wi | C32: 1 | D32: 2 | E32: 3 | F32: 4 | G32: 5 | H32: 6 | I32: 7 | J32: 8 | K32: 9 | L32: 10 | M32: 11 | N32: 12 | O32: 13 | P32: 14 | Q32: 15 | R32: 16 | S32: 17 | T32: 18 | U32: 19 | V32: 20 | W32: 21 | X32: 22 | Y32: 23 | Z32: 24 | AA32: 25 | AB32: 26 | AC32: 27 | AD32: 28 | AE32: 29 | AF32: 30 | AG32: 31 | AH32: 32 | AI32: 33 | AJ32: 34 | AK32: 35 | AL32: 36 | AM32: 37 | AN32: 38 | AO32: 39 | AP32: 40 | AQ32: 41 | AR32: 42 | AS32: 43 | AT32: 44 | AU32: 45 | AV32: 46 | AW32: 47 | AX32: 48 | AY32: 49 | AZ32: 50 | BA32: 51 | BB32: 52 | BC32: 53 | BD32: 54 | BE32: 55 | BF32: 56 | BG32: 57 | BH32: 58 | BI32: 59 | BJ32: 60 | BK32: 61 | BL32: 62 | BM32: 63 | BN32: 64 | BO32: 65 | BP32: 66 | BQ32: 67 | BR32: 68 | BS32: 69 | BT32: 70
A33: Alter | B33: xi | C33: 26 | D33: 21 | E33: 23 | F33: 22 | G33: 20 | H33: 24 | I33: 20 | J33: 19 | K33: 23 | L33: 22 | M33: 26 | N33: 20 | O33: 25 | P33: 22 | Q33: 25 | R33: 22 | S33: 26 | T33: 25 | U33: 22 | V33: 23 | W33: 23 | X33: 23 | Y33: 20 | Z33: 26 | AA33: 21 | AB33: 25 | AC33: 25 | AD33: 22 | AE33: 23
A34: Köperlänge | B34: yi | C34: 184 | D34: 176 | E34: 176 | F34: 188 | G34: 185 | H34: 182 | I34: 183 | J34: 182 | K34: 185 | L34: 160 | M34: 175 | N34: 195 | O34: 176 | P34: 165 | Q34: 180 | R34: 170 | S34: 185 | T34: 178 | U34: 184 | V34: 155 | W34: 178 | X34: 176 | Y34: 183 | Z34: 185 | AA34: 174 | AB34: 176 | AC34: 170 | AD34: 165 | AE34: 160
A35: Berufsausb. | B35: bi | C35: j | D35: n | E35: j | F35: n | G35: n | H35: n | I35: n | J35: n | K35: n | L35: n | M35: j | N35: n | O35: j | P35: n | Q35: n | R35: n | S35: j | T35: n | U35: n | V35: j | W35: n | X35: j | Y35: n | Z35: n | AA35: n | AB35: j | AC35: n | AD35: n | AE35: n
A36: Geschlecht | B36: gi | C36: m | D36: m | E36: m | F36: m | G36: m | H36: m | I36: m | J36: w | K36: m | L36: w | M36: m | N36: m | O36: w | P36: w | Q36: m | R36: m | S36: m | T36: m | U36: m | V36: w | W36: m | X36: m | Y36: m | Z36: m | AA36: w | AB36: w | AC36: m | AD36: w | AE36: w

Sheet Häufigkeiten
A1: Urliste gesamt (Züge a & b) | Q1: Urliste 1 (Zug a) | AG1: Urliste 2 (Zug b)
A2: Alter | E2: Körperlänge | I2: Berufsausbildung | M2: Geschlecht | Q2: Alter | U2: Körperlänge | Y2: Berufsausbildung | AC2: Geschlecht | AG2: Alter | AK2: Körperlänge | AO2: Berufsausbildung | AS2: Geschlecht
B4: =SUM(B7:B100) -> 70 | C4: =SUM(C7:C100) -> 1 | F4: =SUM(F7:F100) -> 70 | G4: =SUM(G7:G100) -> 1 | J4: =SUM(J7:J8) -> 70 | K4: =SUM(K7:K8) -> 1 | N4: =SUM(N7:N8) -> 70 | O4: =SUM(O7:O8) -> 1 | R4: =SUM(R7:R100) -> 41 | S4: =SUM(S7:S100) -> 1 | V4: =SUM(V7:V100) -> 41 | W4: =SUM(W7:W100) -> 1 | Z4: =SUM(Z7:Z8) -> 41 | AA4: =SUM(AA7:AA8) -> 1 | AD4: =SUM(AD7:AD8) -> 41 | AE4: =SUM(AE7:AE8) -> 1 | AH4: =SUM(AH7:AH100) -> 29 | AI4: =SUM(AI7:AI100) -> 1 | AL4: =SUM(AL7:AL100) -> 29 | AM4: =SUM(AM7:AM100) -> 1 | AP4: =SUM(AP7:AP8) -> 29 | AQ4: =SUM(AQ7:AQ8) -> 1 | AT4: =SUM(AT7:AT8) -> 29 | AU4: =SUM(AU7:AU8) -> 1
A6: xi | B6: ni | C6: hi | E6: yi | F6: ni | G6: hi | I6: bi | J6: ni | K6: hi | M6: gi | N6: ni | O6: hi | Q6: xi | R6: ni | S6: hi | U6: yi | V6: ni | W6: hi | Y6: bi | Z6: ni | AA6: hi | AC6: gi | AD6: ni | AE6: hi | AG6: xi | AH6: ni | AI6: hi | AK6: yi | AL6: ni | AM6: hi | AO6: bi | AP6: ni | AQ6: hi | AS6: gi | AT6: ni | AU6: hi
A7: 18 | B7: =COUNTIF(Urlisten!$C$15:$EL$15,A7) -> 0 | C7: =B7/$B$4 -> 0 | E7: 155 | F7: =COUNTIF(Urlisten!$C$16:$EL$16,E7) -> 1 | G7: =F7/$F$4 -> 0.014285714 | I7: j | J7: =COUNTIF(Urlisten!$C$17:$EL$17,I7) -> 17 | K7: =J7/$J$4 -> 0.24285714 | M7: m | N7: =COUNTIF(Urlisten!$C$18:$EL$18,M7) -> 47 | O7: =N7/$N$4 -> 0.67142857 | Q7: =A7 -> 18 | R7: =COUNTIF(Urlisten!$C$25:$BT$25,Q7) -> 0 | S7: =R7/R$4 -> 0 | U7: =E7 -> 155 | V7: =COUNTIF(Urlisten!$C$26:$BT$26,U7) -> 0 | W7: =V7/V$4 -> 0 | Y7: j | Z7: =COUNTIF(Urlisten!$C$27:$BT$27,Y7) -> 9 | AA7: =Z7/Z$4 -> 0.2195122 | AC7: m | AD7: =COUNTIF(Urlisten!$C$28:$BT$28,AC7) -> 27 | AE7: =AD7/AD$4 -> 0.65853659 | AG7: =A7 -> 18 | AH7: =COUNTIF(Urlisten!$C$33:$BT$33,AG7) -> 0 | AI7: =AH7/AH$4 -> 0 | AK7: =E7 -> 155 | AL7: =COUNTIF(Urlisten!$C$34:$BT$34,AK7) -> 1 | AM7: =AL7/AL$4 -> 0.034482759 | AO7: j | AP7: =COUNTIF(Urlisten!$C$35:$BT$35,AO7) -> 8 | AQ7: =AP7/AP$4 -> 0.27586207 | AS7: m | AT7: =COUNTIF(Urlisten!$C$36:$BT$36,AS7) -> 20 | AU7: =AT7/AT$4 -> 0.68965517
A8: =A7+1 -> 19 | B8: =COUNTIF(Urlisten!$C$15:$EL$15,A8) -> 3 | C8: =B8/$B$4 -> 0.042857143 | E8: =E7+1 -> 156 | F8: =COUNTIF(Urlisten!$C$16:$EL$16,E8) -> 0 | G8: =F8/$F$4 -> 0 | I8: n | J8: =COUNTIF(Urlisten!$C$17:$EL$17,I8) -> 53 | K8: =J8/$J$4 -> 0.75714286 | M8: w | N8: =COUNTIF(Urlisten!$C$18:$EL$18,M8) -> 23 | O8: =N8/$N$4 -> 0.32857143 | Q8: =Q7+1 -> 19 | R8: =COUNTIF(Urlisten!$C$25:$BT$25,Q8) -> 2 | S8: =R8/R$4 -> 0.048780488 | U8: =U7+1 -> 156 | V8: =COUNTIF(Urlisten!$C$26:$BT$26,U8) -> 0 | W8: =V8/V$4 -> 0 | Y8: n | Z8: =COUNTIF(Urlisten!$C$27:$BT$27,Y8) -> 32 | AA8: =Z8/Z$4 -> 0.7804878 | AC8: w | AD8: =COUNTIF(Urlisten!$C$28:$BT$28,AC8) -> 14 | AE8: =AD8/AD$4 -> 0.34146341 | AG8: =AG7+1 -> 19 | AH8: =COUNTIF(Urlisten!$C$33:$BT$33,AG8) -> 1 | AI8: =AH8/AH$4 -> 0.034482759 | AK8: =AK7+1 -> 156 | AL8: =COUNTIF(Urlisten!$C$34:$BT$34,AK8) -> 0 | AM8: =AL8/AL$4 -> 0 | AO8: n | AP8: =COUNTIF(Urlisten!$C$35:$BT$35,AO8) -> 21 | AQ8: =AP8/AP$4 -> 0.72413793 | AS8: w | AT8: =COUNTIF(Urlisten!$C$36:$BT$36,AS8) -> 9 | AU8: =AT8/AT$4 -> 0.31034483
A9: =A8+1 -> 20 | B9: =COUNTIF(Urlisten!$C$15:$EL$15,A9) -> 10 | C9: =B9/$B$4 -> 0.14285714 | E9: =E8+1 -> 157 | F9: =COUNTIF(Urlisten!$C$16:$EL$16,E9) -> 0 | G9: =F9/$F$4 -> 0 | Q9: =Q8+1 -> 20 | R9: =COUNTIF(Urlisten!$C$25:$BT$25,Q9) -> 6 | S9: =R9/R$4 -> 0.14634146 | U9: =U8+1 -> 157 | V9: =COUNTIF(Urlisten!$C$26:$BT$26,U9) -> 0 | W9: =V9/V$4 -> 0 | AG9: =AG8+1 -> 20 | AH9: =COUNTIF(Urlisten!$C$33:$BT$33,AG9) -> 4 | AI9: =AH9/AH$4 -> 0.13793103 | AK9: =AK8+1 -> 157 | AL9: =COUNTIF(Urlisten!$C$34:$BT$34,AK9) -> 0 | AM9: =AL9/AL$4 -> 0
A10: =A9+1 -> 21 | B10: =COUNTIF(Urlisten!$C$15:$EL$15,A10) -> 11 | C10: =B10/$B$4 -> 0.15714286 | E10: =E9+1 -> 158 | F10: =COUNTIF(Urlisten!$C$16:$EL$16,E10) -> 0 | G10: =F10/$F$4 -> 0 | Q10: =Q9+1 -> 21 | R10: =COUNTIF(Urlisten!$C$25:$BT$25,Q10) -> 9 | S10: =R10/R$4 -> 0.2195122 | U10: =U9+1 -> 158 | V10: =COUNTIF(Urlisten!$C$26:$BT$26,U10) -> 0 | W10: =V10/V$4 -> 0 | AG10: =AG9+1 -> 21 | AH10: =COUNTIF(Urlisten!$C$33:$BT$33,AG10) -> 2 | AI10: =AH10/AH$4 -> 0.068965517 | AK10: =AK9+1 -> 158 | AL10: =COUNTIF(Urlisten!$C$34:$BT$34,AK10) -> 0 | AM10: =AL10/AL$4 -> 0
A11: =A10+1 -> 22 | B11: =COUNTIF(Urlisten!$C$15:$EL$15,A11) -> 14 | C11: =B11/$B$4 -> 0.2 | E11: =E10+1 -> 159 | F11: =COUNTIF(Urlisten!$C$16:$EL$16,E11) -> 0 | G11: =F11/$F$4 -> 0 | Q11: =Q10+1 -> 22 | R11: =COUNTIF(Urlisten!$C$25:$BT$25,Q11) -> 8 | S11: =R11/R$4 -> 0.19512195 | U11: =U10+1 -> 159 | V11: =COUNTIF(Urlisten!$C$26:$BT$26,U11) -> 0 | W11: =V11/V$4 -> 0 | AG11: =AG10+1 -> 22 | AH11: =COUNTIF(Urlisten!$C$33:$BT$33,AG11) -> 6 | AI11: =AH11/AH$4 -> 0.20689655 | AK11: =AK10+1 -> 159 | AL11: =COUNTIF(Urlisten!$C$34:$BT$34,AK11) -> 0 | AM11: =AL11/AL$4 -> 0
A12: =A11+1 -> 23 | B12: =COUNTIF(Urlisten!$C$15:$EL$15,A12) -> 9 | C12: =B12/$B$4 -> 0.12857143 | E12: =E11+1 -> 160 | F12: =COUNTIF(Urlisten!$C$16:$EL$16,E12) -> 5 | G12: =F12/$F$4 -> 0.071428571 | Q12: =Q11+1 -> 23 | R12: =COUNTIF(Urlisten!$C$25:$BT$25,Q12) -> 3 | S12: =R12/R$4 -> 0.073170732 | U12: =U11+1 -> 160 | V12: =COUNTIF(Urlisten!$C$26:$BT$26,U12) -> 3 | W12: =V12/V$4 -> 0.073170732 | AG12: =AG11+1 -> 23 | AH12: =COUNTIF(Urlisten!$C$33:$BT$33,AG12) -> 6 | AI12: =AH12/AH$4 -> 0.20689655 | AK12: =AK11+1 -> 160 | AL12: =COUNTIF(Urlisten!$C$34:$BT$34,AK12) -> 2 | AM12: =AL12/AL$4 -> 0.068965517
A13: =A12+1 -> 24 | B13: =COUNTIF(Urlisten!$C$15:$EL$15,A13) -> 6 | C13: =B13/$B$4 -> 0.085714286 | E13: =E12+1 -> 161 | F13: =COUNTIF(Urlisten!$C$16:$EL$16,E13) -> 1 | G13: =F13/$F$4 -> 0.014285714 | Q13: =Q12+1 -> 24 | R13: =COUNTIF(Urlisten!$C$25:$BT$25,Q13) -> 5 | S13: =R13/R$4 -> 0.12195122 | U13: =U12+1 -> 161 | V13: =COUNTIF(Urlisten!$C$26:$BT$26,U13) -> 1 | W13: =V13/V$4 -> 0.024390244 | AG13: =AG12+1 -> 24 | AH13: =COUNTIF(Urlisten!$C$33:$BT$33,AG13) -> 1 | AI13: =AH13/AH$4 -> 0.034482759 | AK13: =AK12+1 -> 161 | AL13: =COUNTIF(Urlisten!$C$34:$BT$34,AK13) -> 0 | AM13: =AL13/AL$4 -> 0
A14: =A13+1 -> 25 | B14: =COUNTIF(Urlisten!$C$15:$EL$15,A14) -> 8 | C14: =B14/$B$4 -> 0.11428571 | E14: =E13+1 -> 162 | F14: =COUNTIF(Urlisten!$C$16:$EL$16,E14) -> 0 | G14: =F14/$F$4 -> 0 | Q14: =Q13+1 -> 25 | R14: =COUNTIF(Urlisten!$C$25:$BT$25,Q14) -> 3 | S14: =R14/R$4 -> 0.073170732 | U14: =U13+1 -> 162 | V14: =COUNTIF(Urlisten!$C$26:$BT$26,U14) -> 0 | W14: =V14/V$4 -> 0 | AG14: =AG13+1 -> 25 | AH14: =COUNTIF(Urlisten!$C$33:$BT$33,AG14) -> 5 | AI14: =AH14/AH$4 -> 0.17241379 | AK14: =AK13+1 -> 162 | AL14: =COUNTIF(Urlisten!$C$34:$BT$34,AK14) -> 0 | AM14: =AL14/AL$4 -> 0
A15: =A14+1 -> 26 | B15: =COUNTIF(Urlisten!$C$15:$EL$15,A15) -> 6 | C15: =B15/$B$4 -> 0.085714286 | E15: =E14+1 -> 163 | F15: =COUNTIF(Urlisten!$C$16:$EL$16,E15) -> 3 | G15: =F15/$F$4 -> 0.042857143 | Q15: =Q14+1 -> 26 | R15: =COUNTIF(Urlisten!$C$25:$BT$25,Q15) -> 2 | S15: =R15/R$4 -> 0.048780488 | U15: =U14+1 -> 163 | V15: =COUNTIF(Urlisten!$C$26:$BT$26,U15) -> 3 | W15: =V15/V$4 -> 0.073170732 | AG15: =AG14+1 -> 26 | AH15: =COUNTIF(Urlisten!$C$33:$BT$33,AG15) -> 4 | AI15: =AH15/AH$4 -> 0.13793103 | AK15: =AK14+1 -> 163 | AL15: =COUNTIF(Urlisten!$C$34:$BT$34,AK15) -> 0 | AM15: =AL15/AL$4 -> 0
A16: =A15+1 -> 27 | B16: =COUNTIF(Urlisten!$C$15:$EL$15,A16) -> 1 | C16: =B16/$B$4 -> 0.014285714 | E16: =E15+1 -> 164 | F16: =COUNTIF(Urlisten!$C$16:$EL$16,E16) -> 1 | G16: =F16/$F$4 -> 0.014285714 | Q16: =Q15+1 -> 27 | R16: =COUNTIF(Urlisten!$C$25:$BT$25,Q16) -> 1 | S16: =R16/R$4 -> 0.024390244 | U16: =U15+1 -> 164 | V16: =COUNTIF(Urlisten!$C$26:$BT$26,U16) -> 1 | W16: =V16/V$4 -> 0.024390244 | AG16: =AG15+1 -> 27 | AH16: =COUNTIF(Urlisten!$C$33:$BT$33,AG16) -> 0 | AI16: =AH16/AH$4 -> 0 | AK16: =AK15+1 -> 164 | AL16: =COUNTIF(Urlisten!$C$34:$BT$34,AK16) -> 0 | AM16: =AL16/AL$4 -> 0
A17: =A16+1 -> 28 | B17: =COUNTIF(Urlisten!$C$15:$EL$15,A17) -> 2 | C17: =B17/$B$4 -> 0.028571429 | E17: =E16+1 -> 165 | F17: =COUNTIF(Urlisten!$C$16:$EL$16,E17) -> 3 | G17: =F17/$F$4 -> 0.042857143 | Q17: =Q16+1 -> 28 | R17: =COUNTIF(Urlisten!$C$25:$BT$25,Q17) -> 2 | S17: =R17/R$4 -> 0.048780488 | U17: =U16+1 -> 165 | V17: =COUNTIF(Urlisten!$C$26:$BT$26,U17) -> 1 | W17: =V17/V$4 -> 0.024390244 | AG17: =AG16+1 -> 28 | AH17: =COUNTIF(Urlisten!$C$33:$BT$33,AG17) -> 0 | AI17: =AH17/AH$4 -> 0 | AK17: =AK16+1 -> 165 | AL17: =COUNTIF(Urlisten!$C$34:$BT$34,AK17) -> 2 | AM17: =AL17/AL$4 -> 0.068965517
A18: =A17+1 -> 29 | B18: =COUNTIF(Urlisten!$C$15:$EL$15,A18) -> 0 | C18: =B18/$B$4 -> 0 | E18: =E17+1 -> 166 | F18: =COUNTIF(Urlisten!$C$16:$EL$16,E18) -> 0 | G18: =F18/$F$4 -> 0 | Q18: =Q17+1 -> 29 | R18: =COUNTIF(Urlisten!$C$25:$BT$25,Q18) -> 0 | S18: =R18/R$4 -> 0 | U18: =U17+1 -> 166 | V18: =COUNTIF(Urlisten!$C$26:$BT$26,U18) -> 0 | W18: =V18/V$4 -> 0 | AG18: =AG17+1 -> 29 | AH18: =COUNTIF(Urlisten!$C$33:$BT$33,AG18) -> 0 | AI18: =AH18/AH$4 -> 0 | AK18: =AK17+1 -> 166 | AL18: =COUNTIF(Urlisten!$C$34:$BT$34,AK18) -> 0 | AM18: =AL18/AL$4 -> 0
A19: =A18+1 -> 30 | B19: =COUNTIF(Urlisten!$C$15:$EL$15,A19) -> 0 | C19: =B19/$B$4 -> 0 | E19: =E18+1 -> 167 | F19: =COUNTIF(Urlisten!$C$16:$EL$16,E19) -> 0 | G19: =F19/$F$4 -> 0 | Q19: =Q18+1 -> 30 | R19: =COUNTIF(Urlisten!$C$25:$BT$25,Q19) -> 0 | S19: =R19/R$4 -> 0 | U19: =U18+1 -> 167 | V19: =COUNTIF(Urlisten!$C$26:$BT$26,U19) -> 0 | W19: =V19/V$4 -> 0 | AG19: =AG18+1 -> 30 | AH19: =COUNTIF(Urlisten!$C$33:$BT$33,AG19) -> 0 | AI19: =AH19/AH$4 -> 0 | AK19: =AK18+1 -> 167 | AL19: =COUNTIF(Urlisten!$C$34:$BT$34,AK19) -> 0 | AM19: =AL19/AL$4 -> 0
A20: =A19+1 -> 31 | B20: =COUNTIF(Urlisten!$C$15:$EL$15,A20) -> 0 | C20: =B20/$B$4 -> 0 | E20: =E19+1 -> 168 | F20: =COUNTIF(Urlisten!$C$16:$EL$16,E20) -> 1 | G20: =F20/$F$4 -> 0.014285714 | Q20: =Q19+1 -> 31 | R20: =COUNTIF(Urlisten!$C$25:$BT$25,Q20) -> 0 | S20: =R20/R$4 -> 0 | U20: =U19+1 -> 168 | V20: =COUNTIF(Urlisten!$C$26:$BT$26,U20) -> 1 | W20: =V20/V$4 -> 0.024390244 | AG20: =AG19+1 -> 31 | AH20: =COUNTIF(Urlisten!$C$33:$BT$33,AG20) -> 0 | AI20: =AH20/AH$4 -> 0 | AK20: =AK19+1 -> 168 | AL20: =COUNTIF(Urlisten!$C$34:$BT$34,AK20) -> 0 | AM20: =AL20/AL$4 -> 0
... A31: =A30+1 -> 42 | B31: =COUNTIF(Urlisten!$C$15:$EL$15,A31) -> 0 | C31: =B31/$B$4 -> 0 | E31: =E30+1 -> 179 | F31: =COUNTIF(Urlisten!$C$16:$EL$16,E31) -> 0 | G31: =F31/$F$4 -> 0 | Q31: =Q30+1 -> 42 | R31: =COUNTIF(Urlisten!$C$25:$BT$25,Q31) -> 0 | S31: =R31/R$4 -> 0 | U31: =U30+1 -> 179 | V31: =COUNTIF(Urlisten!$C$26:$BT$26,U31) -> 0 | W31: =V31/V$4 -> 0 | AG31: =AG30+1 -> 42 | AH31: =COUNTIF(Urlisten!$C$33:$BT$33,AG31) -> 0 | AI31: =AH31/AH$4 -> 0 | AK31: =AK30+1 -> 179 | AL31: =COUNTIF(Urlisten!$C$34:$BT$34,AK31) -> 0 | AM31: =AL31/AL$4 -> 0
E32: =E31+1 -> 180 | F32: =COUNTIF(Urlisten!$C$16:$EL$16,E32) -> 4 | G32: =F32/$F$4 -> 0.057142857 | U32: =U31+1 -> 180 | V32: =COUNTIF(Urlisten!$C$26:$BT$26,U32) -> 3 | W32: =V32/V$4 -> 0.073170732 | AK32: =AK31+1 -> 180 | AL32: =COUNTIF(Urlisten!$C$34:$BT$34,AK32) -> 1 | AM32: =AL32/AL$4 -> 0.034482759
E33: =E32+1 -> 181 | F33: =COUNTIF(Urlisten!$C$16:$EL$16,E33) -> 0 | G33: =F33/$F$4 -> 0 | U33: =U32+1 -> 181 | V33: =COUNTIF(Urlisten!$C$26:$BT$26,U33) -> 0 | W33: =V33/V$4 -> 0 | AK33: =AK32+1 -> 181 | AL33: =COUNTIF(Urlisten!$C$34:$BT$34,AK33) -> 0 | AM33: =AL33/AL$4 -> 0
E34: =E33+1 -> 182 | F34: =COUNTIF(Urlisten!$C$16:$EL$16,E34) -> 5 | G34: =F34/$F$4 -> 0.071428571 | U34: =U33+1 -> 182 | V34: =COUNTIF(Urlisten!$C$26:$BT$26,U34) -> 3 | W34: =V34/V$4 -> 0.073170732 | AK34: =AK33+1 -> 182 | AL34: =COUNTIF(Urlisten!$C$34:$BT$34,AK34) -> 2 | AM34: =AL34/AL$4 -> 0.068965517
E35: =E34+1 -> 183 | F35: =COUNTIF(Urlisten!$C$16:$EL$16,E35) -> 4 | G35: =F35/$F$4 -> 0.057142857 | U35: =U34+1 -> 183 | V35: =COUNTIF(Urlisten!$C$26:$BT$26,U35) -> 2 | W35: =V35/V$4 -> 0.048780488 | AK35: =AK34+1 -> 183 | AL35: =COUNTIF(Urlisten!$C$34:$BT$34,AK35) -> 2 | AM35: =AL35/AL$4 -> 0.068965517
E36: =E35+1 -> 184 | F36: =COUNTIF(Urlisten!$C$16:$EL$16,E36) -> 3 | G36: =F36/$F$4 -> 0.042857143 | U36: =U35+1 -> 184 | V36: =COUNTIF(Urlisten!$C$26:$BT$26,U36) -> 1 | W36: =V36/V$4 -> 0.024390244 | AK36: =AK35+1 -> 184 | AL36: =COUNTIF(Urlisten!$C$34:$BT$34,AK36) -> 2 | AM36: =AL36/AL$4 -> 0.068965517
E37: =E36+1 -> 185 | F37: =COUNTIF(Urlisten!$C$16:$EL$16,E37) -> 7 | G37: =F37/$F$4 -> 0.1 | U37: =U36+1 -> 185 | V37: =COUNTIF(Urlisten!$C$26:$BT$26,U37) -> 3 | W37: =V37/V$4 -> 0.073170732 | AK37: =AK36+1 -> 185 | AL37: =COUNTIF(Urlisten!$C$34:$BT$34,AK37) -> 4 | AM37: =AL37/AL$4 -> 0.13793103
E38: =E37+1 -> 186 | F38: =COUNTIF(Urlisten!$C$16:$EL$16,E38) -> 0 | G38: =F38/$F$4 -> 0 | U38: =U37+1 -> 186 | V38: =COUNTIF(Urlisten!$C$26:$BT$26,U38) -> 0 | W38: =V38/V$4 -> 0 | AK38: =AK37+1 -> 186 | AL38: =COUNTIF(Urlisten!$C$34:$BT$34,AK38) -> 0 | AM38: =AL38/AL$4 -> 0
E39: =E38+1 -> 187 | F39: =COUNTIF(Urlisten!$C$16:$EL$16,E39) -> 2 | G39: =F39/$F$4 -> 0.028571429 | U39: =U38+1 -> 187 | V39: =COUNTIF(Urlisten!$C$26:$BT$26,U39) -> 2 | W39: =V39/V$4 -> 0.048780488 | AK39: =AK38+1 -> 187 | AL39: =COUNTIF(Urlisten!$C$34:$BT$34,AK39) -> 0 | AM39: =AL39/AL$4 -> 0
E40: =E39+1 -> 188 | F40: =COUNTIF(Urlisten!$C$16:$EL$16,E40) -> 1 | G40: =F40/$F$4 -> 0.014285714 | U40: =U39+1 -> 188 | V40: =COUNTIF(Urlisten!$C$26:$BT$26,U40) -> 0 | W40: =V40/V$4 -> 0 | AK40: =AK39+1 -> 188 | AL40: =COUNTIF(Urlisten!$C$34:$BT$34,AK40) -> 1 | AM40: =AL40/AL$4 -> 0.034482759
E41: =E40+1 -> 189 | F41: =COUNTIF(Urlisten!$C$16:$EL$16,E41) -> 1 | G41: =F41/$F$4 -> 0.014285714 | U41: =U40+1 -> 189 | V41: =COUNTIF(Urlisten!$C$26:$BT$26,U41) -> 1 | W41: =V41/V$4 -> 0.024390244 | AK41: =AK40+1 -> 189 | AL41: =COUNTIF(Urlisten!$C$34:$BT$34,AK41) -> 0 | AM41: =AL41/AL$4 -> 0
E42: =E41+1 -> 190 | F42: =COUNTIF(Urlisten!$C$16:$EL$16,E42) -> 1 | G42: =F42/$F$4 -> 0.014285714 | U42: =U41+1 -> 190 | V42: =COUNTIF(Urlisten!$C$26:$BT$26,U42) -> 1 | W42: =V42/V$4 -> 0.024390244 | AK42: =AK41+1 -> 190 | AL42: =COUNTIF(Urlisten!$C$34:$BT$34,AK42) -> 0 | AM42: =AL42/AL$4 -> 0
E43: =E42+1 -> 191 | F43: =COUNTIF(Urlisten!$C$16:$EL$16,E43) -> 0 | G43: =F43/$F$4 -> 0 | U43: =U42+1 -> 191 | V43: =COUNTIF(Urlisten!$C$26:$BT$26,U43) -> 0 | W43: =V43/V$4 -> 0 | AK43: =AK42+1 -> 191 | AL43: =COUNTIF(Urlisten!$C$34:$BT$34,AK43) -> 0 | AM43: =AL43/AL$4 -> 0
... E51: =E50+1 -> 199 | F51: =COUNTIF(Urlisten!$C$16:$EL$16,E51) -> 0 | G51: =F51/$F$4 -> 0 | U51: =U50+1 -> 199 | V51: =COUNTIF(Urlisten!$C$26:$BT$26,U51) -> 0 | W51: =V51/V$4 -> 0 | AK51: =AK50+1 -> 199 | AL51: =COUNTIF(Urlisten!$C$34:$BT$34,AK51) -> 0 | AM51: =AL51/AL$4 -> 0

Sheet Häufigkeiten 2
A1: Urliste gesamt (Züge a & b) | Q1: Urliste 1 (Zug a) | AG1: Urliste 2 (Zug b)
A2: Alter | E2: Körperlänge | I2: Berufsausbildung | M2: Geschlecht | Q2: Alter | U2: Körperlänge | Y2: Berufsausbildung | AC2: Geschlecht | AG2: Alter | AK2: Körperlänge | AO2: Berufsausbildung | AS2: Geschlecht
B4: =SUM(B7:B85) -> 70 | C4: =SUM(C7:C85) -> 1 | F4: =SUM(F7:F82) -> 70 | G4: =SUM(G7:G82) -> 1 | J4: =SUM(J7:J8) -> 70 | K4: =SUM(K7:K8) -> 1 | N4: =SUM(N7:N8) -> 70 | O4: =SUM(O7:O8) -> 1 | R4: =SUM(R7:R85) -> 41 | S4: =SUM(S7:S85) -> 1 | V4: =SUM(V7:V78) -> 41 | W4: =SUM(W7:W78) -> 1 | Z4: =SUM(Z7:Z8) -> 41 | AA4: =SUM(AA7:AA8) -> 1 | AD4: =SUM(AD7:AD8) -> 41 | AE4: =SUM(AE7:AE8) -> 1 | AH4: =SUM(AH7:AH83) -> 29 | AI4: =SUM(AI7:AI83) -> 1 | AL4: =SUM(AL7:AL70) -> 29 | AM4: =SUM(AM7:AM70) -> 1 | AP4: =SUM(AP7:AP8) -> 29 | AQ4: =SUM(AQ7:AQ8) -> 1 | AT4: =SUM(AT7:AT8) -> 29 | AU4: =SUM(AU7:AU8) -> 1
A6: xi | B6: ni | C6: hi | E6: yi | F6: ni | G6: hi | I6: bi | J6: ni | K6: hi | M6: gi | N6: ni | O6: hi | Q6: xi | R6: ni | S6: hi | U6: yi | V6: ni | W6: hi | Y6: bi | Z6: ni | AA6: hi | AC6: gi | AD6: ni | AE6: hi | AG6: xi | AH6: ni | AI6: hi | AK6: yi | AL6: ni | AM6: hi | AO6: bi | AP6: ni | AQ6: hi | AS6: gi | AT6: ni | AU6: hi
A7: 19 | B7: 3 | C7: 0.042857143 | E7: 155 | F7: 1 | G7: 0.014285714 | I7: j | J7: 17 | K7: 0.24285714 | M7: m | N7: 47 | O7: 0.67142857 | Q7: 19 | R7: 2 | S7: 0.048780488 | U7: 160 | V7: 3 | W7: 0.073170732 | Y7: j | Z7: 9 | AA7: 0.2195122 | AC7: m | AD7: 27 | AE7: 0.65853659 | AG7: 19 | AH7: 1 | AI7: 0.034482759 | AK7: 155 | AL7: 1 | AM7: 0.034482759 | AO7: j | AP7: 8 | AQ7: 0.27586207 | AS7: m | AT7: 20 | AU7: 0.68965517
A8: 20 | B8: 10 | C8: 0.14285714 | E8: 160 | F8: 5 | G8: 0.071428571 | I8: n | J8: 53 | K8: 0.75714286 | M8: w | N8: 23 | O8: 0.32857143 | Q8: 20 | R8: 6 | S8: 0.14634146 | U8: 161 | V8: 1 | W8: 0.024390244 | Y8: n | Z8: 32 | AA8: 0.7804878 | AC8: w | AD8: 14 | AE8: 0.34146341 | AG8: 20 | AH8: 4 | AI8: 0.13793103 | AK8: 160 | AL8: 2 | AM8: 0.068965517 | AO8: n | AP8: 21 | AQ8: 0.72413793 | AS8: w | AT8: 9 | AU8: 0.31034483
A9: 21 | B9: 11 | C9: 0.15714286 | E9: 161 | F9: 1 | G9: 0.014285714 | Q9: 21 | R9: 9 | S9: 0.2195122 | U9: 163 | V9: 3 | W9: 0.073170732 | AG9: 21 | AH9: 2 | AI9: 0.068965517 | AK9: 165 | AL9: 2 | AM9: 0.068965517
A10: 22 | B10: 14 | C10: 0.2 | E10: 163 | F10: 3 | G10: 0.042857143 | Q10: 22 | R10: 8 | S10: 0.19512195 | U10: 164 | V10: 1 | W10: 0.024390244 | AG10: 22 | AH10: 6 | AI10: 0.20689655 | AK10: 170 | AL10: 2 | AM10: 0.068965517
A11: 23 | B11: 9 | C11: 0.12857143 | E11: 164 | F11: 1 | G11: 0.014285714 | Q11: 23 | R11: 3 | S11: 0.073170732 | U11: 165 | V11: 1 | W11: 0.024390244 | AG11: 23 | AH11: 6 | AI11: 0.20689655 | AK11: 174 | AL11: 1 | AM11: 0.034482759
A12: 24 | B12: 6 | C12: 0.085714286 | E12: 165 | F12: 3 | G12: 0.042857143 | Q12: 24 | R12: 5 | S12: 0.12195122 | U12: 168 | V12: 1 | W12: 0.024390244 | AG12: 24 | AH12: 1 | AI12: 0.034482759 | AK12: 175 | AL12: 1 | AM12: 0.034482759
A13: 25 | B13: 8 | C13: 0.11428571 | E13: 168 | F13: 1 | G13: 0.014285714 | Q13: 25 | R13: 3 | S13: 0.073170732 | U13: 169 | V13: 1 | W13: 0.024390244 | AG13: 25 | AH13: 5 | AI13: 0.17241379 | AK13: 176 | AL13: 5 | AM13: 0.17241379
A14: 26 | B14: 6 | C14: 0.085714286 | E14: 169 | F14: 1 | G14: 0.014285714 | Q14: 26 | R14: 2 | S14: 0.048780488 | U14: 170 | V14: 5 | W14: 0.12195122 | AG14: 26 | AH14: 4 | AI14: 0.13793103 | AK14: 178 | AL14: 2 | AM14: 0.068965517
A15: 27 | B15: 1 | C15: 0.014285714 | E15: 170 | F15: 7 | G15: 0.1 | Q15: 27 | R15: 1 | S15: 0.024390244 | U15: 171 | V15: 1 | W15: 0.024390244 | AK15: 180 | AL15: 1 | AM15: 0.034482759
